[2025-08-29 19:18:29,540] {taskinstance.py:1159} INFO - Dependencies all met for <TaskInstance: send_weather_to_kafka.fetch_and_send_weather scheduled__2025-08-19T13:04:41.720997+00:00 [queued]>
[2025-08-29 19:18:29,567] {taskinstance.py:1159} INFO - Dependencies all met for <TaskInstance: send_weather_to_kafka.fetch_and_send_weather scheduled__2025-08-19T13:04:41.720997+00:00 [queued]>
[2025-08-29 19:18:29,568] {taskinstance.py:1356} INFO - 
--------------------------------------------------------------------------------
[2025-08-29 19:18:29,568] {taskinstance.py:1357} INFO - Starting attempt 1 of 2
[2025-08-29 19:18:29,568] {taskinstance.py:1358} INFO - 
--------------------------------------------------------------------------------
[2025-08-29 19:18:29,610] {taskinstance.py:1377} INFO - Executing <Task(BashOperator): fetch_and_send_weather> on 2025-08-19 13:04:41.720997+00:00
[2025-08-29 19:18:29,625] {standard_task_runner.py:52} INFO - Started process 190 to run task
[2025-08-29 19:18:29,642] {standard_task_runner.py:79} INFO - Running: ['***', 'tasks', 'run', 'send_weather_to_kafka', 'fetch_and_send_weather', 'scheduled__2025-08-19T13:04:41.720997+00:00', '--job-id', '351', '--raw', '--subdir', 'DAGS_FOLDER/dag_meteo.py', '--cfg-path', '/tmp/tmpefv_kdh8', '--error-file', '/tmp/tmpvknd_y1h']
[2025-08-29 19:18:29,644] {standard_task_runner.py:80} INFO - Job 351: Subtask fetch_and_send_weather
[2025-08-29 19:18:29,680] {logging_mixin.py:115} WARNING - /home/***/.local/lib/python3.7/site-packages/***/configuration.py:470 DeprecationWarning: The sql_alchemy_conn option in [core] has been moved to the sql_alchemy_conn option in [database] - the old setting has been used, but please update your config.
[2025-08-29 19:18:29,852] {task_command.py:369} INFO - Running <TaskInstance: send_weather_to_kafka.fetch_and_send_weather scheduled__2025-08-19T13:04:41.720997+00:00 [running]> on host a4b544519f2b
[2025-08-29 19:18:30,162] {taskinstance.py:1571} INFO - Exporting the following env vars:
AIRFLOW_CTX_DAG_OWNER=***
AIRFLOW_CTX_DAG_ID=send_weather_to_kafka
AIRFLOW_CTX_TASK_ID=fetch_and_send_weather
AIRFLOW_CTX_EXECUTION_DATE=2025-08-19T13:04:41.720997+00:00
AIRFLOW_CTX_TRY_NUMBER=1
AIRFLOW_CTX_DAG_RUN_ID=scheduled__2025-08-19T13:04:41.720997+00:00
[2025-08-29 19:18:30,163] {subprocess.py:62} INFO - Tmp dir root location: 
 /tmp
[2025-08-29 19:18:30,165] {subprocess.py:74} INFO - Running command: ['bash', '-c', 'cd /opt/***/scripts && python3 kafka/producer.py']
[2025-08-29 19:18:30,192] {subprocess.py:85} INFO - Output:
[2025-08-29 19:18:34,706] {subprocess.py:92} INFO - Traceback (most recent call last):
[2025-08-29 19:18:34,707] {subprocess.py:92} INFO -   File "kafka/producer.py", line 14, in <module>
[2025-08-29 19:18:34,707] {subprocess.py:92} INFO -     value_serializer=lambda v: json.dumps(v).encode('utf-8')
[2025-08-29 19:18:34,707] {subprocess.py:92} INFO -   File "/home/***/.local/lib/python3.7/site-packages/kafka/producer/kafka.py", line 485, in __init__
[2025-08-29 19:18:34,707] {subprocess.py:92} INFO -     **self.config)
[2025-08-29 19:18:34,707] {subprocess.py:92} INFO -   File "/home/***/.local/lib/python3.7/site-packages/kafka/client_async.py", line 262, in __init__
[2025-08-29 19:18:34,707] {subprocess.py:92} INFO -     self.config['api_version'] = self.check_version()
[2025-08-29 19:18:34,707] {subprocess.py:92} INFO -   File "/home/***/.local/lib/python3.7/site-packages/kafka/client_async.py", line 1078, in check_version
[2025-08-29 19:18:34,707] {subprocess.py:92} INFO -     raise Errors.NoBrokersAvailable()
[2025-08-29 19:18:34,707] {subprocess.py:92} INFO - kafka.errors.NoBrokersAvailable: NoBrokersAvailable
[2025-08-29 19:18:34,875] {subprocess.py:96} INFO - Command exited with return code 1
[2025-08-29 19:18:34,932] {taskinstance.py:1889} ERROR - Task failed with exception
Traceback (most recent call last):
  File "/home/airflow/.local/lib/python3.7/site-packages/airflow/operators/bash.py", line 195, in execute
    f'Bash command failed. The command returned a non-zero exit code {result.exit_code}.'
airflow.exceptions.AirflowException: Bash command failed. The command returned a non-zero exit code 1.
[2025-08-29 19:18:34,952] {taskinstance.py:1400} INFO - Marking task as UP_FOR_RETRY. dag_id=send_weather_to_kafka, task_id=fetch_and_send_weather, execution_date=20250819T130441, start_date=20250829T191829, end_date=20250829T191834
[2025-08-29 19:18:35,036] {standard_task_runner.py:97} ERROR - Failed to execute job 351 for task fetch_and_send_weather (Bash command failed. The command returned a non-zero exit code 1.; 190)
[2025-08-29 19:18:35,096] {local_task_job.py:156} INFO - Task exited with return code 1
[2025-08-29 19:18:35,241] {local_task_job.py:273} INFO - 0 downstream tasks scheduled from follow-on schedule check
