[2025-08-19 02:06:23,475] {taskinstance.py:1159} INFO - Dependencies all met for <TaskInstance: send_weather_to_kafka.fetch_and_send_weather scheduled__2025-08-19T00:06:22.703055+00:00 [queued]>
[2025-08-19 02:06:23,505] {taskinstance.py:1159} INFO - Dependencies all met for <TaskInstance: send_weather_to_kafka.fetch_and_send_weather scheduled__2025-08-19T00:06:22.703055+00:00 [queued]>
[2025-08-19 02:06:23,505] {taskinstance.py:1356} INFO - 
--------------------------------------------------------------------------------
[2025-08-19 02:06:23,505] {taskinstance.py:1357} INFO - Starting attempt 1 of 2
[2025-08-19 02:06:23,505] {taskinstance.py:1358} INFO - 
--------------------------------------------------------------------------------
[2025-08-19 02:06:23,542] {taskinstance.py:1377} INFO - Executing <Task(BashOperator): fetch_and_send_weather> on 2025-08-19 00:06:22.703055+00:00
[2025-08-19 02:06:23,550] {standard_task_runner.py:52} INFO - Started process 9234 to run task
[2025-08-19 02:06:23,557] {standard_task_runner.py:79} INFO - Running: ['***', 'tasks', 'run', 'send_weather_to_kafka', 'fetch_and_send_weather', 'scheduled__2025-08-19T00:06:22.703055+00:00', '--job-id', '304', '--raw', '--subdir', 'DAGS_FOLDER/dag_meteo.py', '--cfg-path', '/tmp/tmp6azu4prk', '--error-file', '/tmp/tmpgb78kx1x']
[2025-08-19 02:06:23,560] {standard_task_runner.py:80} INFO - Job 304: Subtask fetch_and_send_weather
[2025-08-19 02:06:23,596] {logging_mixin.py:115} WARNING - /home/***/.local/lib/python3.7/site-packages/***/configuration.py:470 DeprecationWarning: The sql_alchemy_conn option in [core] has been moved to the sql_alchemy_conn option in [database] - the old setting has been used, but please update your config.
[2025-08-19 02:06:23,693] {task_command.py:369} INFO - Running <TaskInstance: send_weather_to_kafka.fetch_and_send_weather scheduled__2025-08-19T00:06:22.703055+00:00 [running]> on host a4b544519f2b
[2025-08-19 02:06:23,832] {taskinstance.py:1571} INFO - Exporting the following env vars:
AIRFLOW_CTX_DAG_OWNER=***
AIRFLOW_CTX_DAG_ID=send_weather_to_kafka
AIRFLOW_CTX_TASK_ID=fetch_and_send_weather
AIRFLOW_CTX_EXECUTION_DATE=2025-08-19T00:06:22.703055+00:00
AIRFLOW_CTX_TRY_NUMBER=1
AIRFLOW_CTX_DAG_RUN_ID=scheduled__2025-08-19T00:06:22.703055+00:00
[2025-08-19 02:06:23,833] {subprocess.py:62} INFO - Tmp dir root location: 
 /tmp
[2025-08-19 02:06:23,834] {subprocess.py:74} INFO - Running command: ['bash', '-c', 'cd /opt/***/scripts && python3 kafka/producer.py']
[2025-08-19 02:06:23,849] {subprocess.py:85} INFO - Output:
[2025-08-19 02:06:25,126] {subprocess.py:92} INFO - Traceback (most recent call last):
[2025-08-19 02:06:25,127] {subprocess.py:92} INFO -   File "/home/***/.local/lib/python3.7/site-packages/urllib3/connection.py", line 175, in _new_conn
[2025-08-19 02:06:25,127] {subprocess.py:92} INFO -     (self._dns_host, self.port), self.timeout, **extra_kw
[2025-08-19 02:06:25,127] {subprocess.py:92} INFO -   File "/home/***/.local/lib/python3.7/site-packages/urllib3/util/connection.py", line 72, in create_connection
[2025-08-19 02:06:25,127] {subprocess.py:92} INFO -     for res in socket.getaddrinfo(host, port, family, socket.SOCK_STREAM):
[2025-08-19 02:06:25,127] {subprocess.py:92} INFO -   File "/usr/local/lib/python3.7/socket.py", line 752, in getaddrinfo
[2025-08-19 02:06:25,127] {subprocess.py:92} INFO -     for res in _socket.getaddrinfo(host, port, family, type, proto, flags):
[2025-08-19 02:06:25,128] {subprocess.py:92} INFO - socket.gaierror: [Errno -3] Temporary failure in name resolution
[2025-08-19 02:06:25,128] {subprocess.py:92} INFO - 
[2025-08-19 02:06:25,128] {subprocess.py:92} INFO - During handling of the above exception, another exception occurred:
[2025-08-19 02:06:25,128] {subprocess.py:92} INFO - 
[2025-08-19 02:06:25,128] {subprocess.py:92} INFO - Traceback (most recent call last):
[2025-08-19 02:06:25,128] {subprocess.py:92} INFO -   File "/home/***/.local/lib/python3.7/site-packages/urllib3/connectionpool.py", line 710, in urlopen
[2025-08-19 02:06:25,128] {subprocess.py:92} INFO -     chunked=chunked,
[2025-08-19 02:06:25,128] {subprocess.py:92} INFO -   File "/home/***/.local/lib/python3.7/site-packages/urllib3/connectionpool.py", line 386, in _make_request
[2025-08-19 02:06:25,129] {subprocess.py:92} INFO -     self._validate_conn(conn)
[2025-08-19 02:06:25,129] {subprocess.py:92} INFO -   File "/home/***/.local/lib/python3.7/site-packages/urllib3/connectionpool.py", line 1040, in _validate_conn
[2025-08-19 02:06:25,129] {subprocess.py:92} INFO -     conn.connect()
[2025-08-19 02:06:25,129] {subprocess.py:92} INFO -   File "/home/***/.local/lib/python3.7/site-packages/urllib3/connection.py", line 358, in connect
[2025-08-19 02:06:25,129] {subprocess.py:92} INFO -     self.sock = conn = self._new_conn()
[2025-08-19 02:06:25,129] {subprocess.py:92} INFO -   File "/home/***/.local/lib/python3.7/site-packages/urllib3/connection.py", line 187, in _new_conn
[2025-08-19 02:06:25,129] {subprocess.py:92} INFO -     self, "Failed to establish a new connection: %s" % e
[2025-08-19 02:06:25,129] {subprocess.py:92} INFO - urllib3.exceptions.NewConnectionError: <urllib3.connection.HTTPSConnection object at 0x7eaefe721190>: Failed to establish a new connection: [Errno -3] Temporary failure in name resolution
[2025-08-19 02:06:25,129] {subprocess.py:92} INFO - 
[2025-08-19 02:06:25,130] {subprocess.py:92} INFO - During handling of the above exception, another exception occurred:
[2025-08-19 02:06:25,130] {subprocess.py:92} INFO - 
[2025-08-19 02:06:25,130] {subprocess.py:92} INFO - Traceback (most recent call last):
[2025-08-19 02:06:25,130] {subprocess.py:92} INFO -   File "/home/***/.local/lib/python3.7/site-packages/requests/adapters.py", line 497, in send
[2025-08-19 02:06:25,130] {subprocess.py:92} INFO -     chunked=chunked,
[2025-08-19 02:06:25,130] {subprocess.py:92} INFO -   File "/home/***/.local/lib/python3.7/site-packages/urllib3/connectionpool.py", line 786, in urlopen
[2025-08-19 02:06:25,130] {subprocess.py:92} INFO -     method, url, error=e, _pool=self, _stacktrace=sys.exc_info()[2]
[2025-08-19 02:06:25,130] {subprocess.py:92} INFO -   File "/home/***/.local/lib/python3.7/site-packages/urllib3/util/retry.py", line 592, in increment
[2025-08-19 02:06:25,130] {subprocess.py:92} INFO -     raise MaxRetryError(_pool, url, error or ResponseError(cause))
[2025-08-19 02:06:25,131] {subprocess.py:92} INFO - urllib3.exceptions.MaxRetryError: HTTPSConnectionPool(host='api.tomorrow.io', port=443): Max retries exceeded with url: /v4/weather/realtime?location=14.6937,-17.4441&apikey=OC9yH405dZFT1BOO6w6nPgDanrhpPwV8 (Caused by NewConnectionError('<urllib3.connection.HTTPSConnection object at 0x7eaefe721190>: Failed to establish a new connection: [Errno -3] Temporary failure in name resolution'))
[2025-08-19 02:06:25,131] {subprocess.py:92} INFO - 
[2025-08-19 02:06:25,131] {subprocess.py:92} INFO - During handling of the above exception, another exception occurred:
[2025-08-19 02:06:25,131] {subprocess.py:92} INFO - 
[2025-08-19 02:06:25,131] {subprocess.py:92} INFO - Traceback (most recent call last):
[2025-08-19 02:06:25,131] {subprocess.py:92} INFO -   File "kafka/producer.py", line 47, in <module>
[2025-08-19 02:06:25,131] {subprocess.py:92} INFO -     run()
[2025-08-19 02:06:25,131] {subprocess.py:92} INFO -   File "kafka/producer.py", line 38, in run
[2025-08-19 02:06:25,131] {subprocess.py:92} INFO -     weather_data = get_weather()
[2025-08-19 02:06:25,131] {subprocess.py:92} INFO -   File "kafka/producer.py", line 20, in get_weather
[2025-08-19 02:06:25,132] {subprocess.py:92} INFO -     response = requests.get(url)
[2025-08-19 02:06:25,132] {subprocess.py:92} INFO -   File "/home/***/.local/lib/python3.7/site-packages/requests/api.py", line 73, in get
[2025-08-19 02:06:25,132] {subprocess.py:92} INFO -     return request("get", url, params=params, **kwargs)
[2025-08-19 02:06:25,132] {subprocess.py:92} INFO -   File "/home/***/.local/lib/python3.7/site-packages/requests/api.py", line 59, in request
[2025-08-19 02:06:25,132] {subprocess.py:92} INFO -     return session.request(method=method, url=url, **kwargs)
[2025-08-19 02:06:25,132] {subprocess.py:92} INFO -   File "/home/***/.local/lib/python3.7/site-packages/requests/sessions.py", line 589, in request
[2025-08-19 02:06:25,132] {subprocess.py:92} INFO -     resp = self.send(prep, **send_kwargs)
[2025-08-19 02:06:25,132] {subprocess.py:92} INFO -   File "/home/***/.local/lib/python3.7/site-packages/requests/sessions.py", line 703, in send
[2025-08-19 02:06:25,132] {subprocess.py:92} INFO -     r = adapter.send(request, **kwargs)
[2025-08-19 02:06:25,133] {subprocess.py:92} INFO -   File "/home/***/.local/lib/python3.7/site-packages/requests/adapters.py", line 519, in send
[2025-08-19 02:06:25,133] {subprocess.py:92} INFO -     raise ConnectionError(e, request=request)
[2025-08-19 02:06:25,133] {subprocess.py:92} INFO - requests.exceptions.ConnectionError: HTTPSConnectionPool(host='api.tomorrow.io', port=443): Max retries exceeded with url: /v4/weather/realtime?location=14.6937,-17.4441&apikey=OC9yH405dZFT1BOO6w6nPgDanrhpPwV8 (Caused by NewConnectionError('<urllib3.connection.HTTPSConnection object at 0x7eaefe721190>: Failed to establish a new connection: [Errno -3] Temporary failure in name resolution'))
[2025-08-19 02:06:25,268] {subprocess.py:96} INFO - Command exited with return code 1
[2025-08-19 02:06:25,315] {taskinstance.py:1889} ERROR - Task failed with exception
Traceback (most recent call last):
  File "/home/airflow/.local/lib/python3.7/site-packages/airflow/operators/bash.py", line 195, in execute
    f'Bash command failed. The command returned a non-zero exit code {result.exit_code}.'
airflow.exceptions.AirflowException: Bash command failed. The command returned a non-zero exit code 1.
[2025-08-19 02:06:25,324] {taskinstance.py:1400} INFO - Marking task as UP_FOR_RETRY. dag_id=send_weather_to_kafka, task_id=fetch_and_send_weather, execution_date=20250819T000622, start_date=20250819T020623, end_date=20250819T020625
[2025-08-19 02:06:25,350] {standard_task_runner.py:97} ERROR - Failed to execute job 304 for task fetch_and_send_weather (Bash command failed. The command returned a non-zero exit code 1.; 9234)
[2025-08-19 02:06:25,374] {local_task_job.py:156} INFO - Task exited with return code 1
[2025-08-19 02:06:25,466] {local_task_job.py:273} INFO - 0 downstream tasks scheduled from follow-on schedule check
